2021/10/29 11:47:44 [error] 32#32: *1 connect() failed (111: Connection refused) while connecting to upstream, client: 172.20.0.1, server: localhost, request: "GET /api/cenotes/bounds HTTP/1.1", upstream: "http://172.20.0.2:8529/_db/cenoteando/api/cenotes/bounds", host: "localhost", referrer: "http://localhost:8080/"
2021/10/29 11:51:51 [error] 33#33: *1 connect() failed (111: Connection refused) while connecting to upstream, client: 172.21.0.1, server: localhost, request: "GET /api/cenotes/bounds HTTP/1.1", upstream: "http://172.21.0.2:8529/_db/cenoteando/api/cenotes/bounds", host: "localhost", referrer: "http://localhost:8080/"
2021/11/01 10:17:08 [error] 32#32: *2 connect() failed (111: Connection refused) while connecting to upstream, client: 172.20.0.1, server: localhost, request: "GET /api/cenotes/bounds HTTP/1.1", upstream: "http://172.20.0.2:8529/_db/cenoteando/api/cenotes/bounds", host: "localhost", referrer: "http://localhost:8080/"
